Workbook

Sheet Start Here
A1: Start Here
A2: A full year of budgeting that does the math for you.
A4: HOW IT WORKS
A5: 1. Setup | C5: Set your year and currency, then list your categories and accounts.
A6: 2. Transactions | C6: Log every income, expense and transfer once. Months and totals fill in automatically.
A7: 3. Annual Dashboard | C7: See your whole year: monthly totals, category trends, 50/30/20 and charts.
A9: THE TABS
A10: Annual Dashboard | C10: Your full year at a glance. Updates itself.
A11: 50 / 30 / 20 Rule | C11: How your spending splits into needs, wants and savings, vs the 50/30/20 targets.
A12: Spending Tracker | C12: Which categories take the biggest share of your spending this year.
A13: Month View | C13: Pick any month to see it on its own.
A14: Bill Calendar | C14: Weekly to yearly bills shown as a fair monthly and yearly cost.
A15: Savings & Net Worth
A17: COLOR KEY
A18: Blue text | C18: You type it.
A19: Dark text | C19: Calculated — do not edit.
A21: Works in Google Sheets AND Excel. One log feeds the whole year — no separate tab per month.
A22: Formulas are protected, only the blue cells are yours.
A23: This is an organisation tool, not financial advice.

Sheet Setup
A1: Setup
A2: Edit once — your year, currency, categories and accounts. | M2: COUPLE SETUP
M3: Partner A name | N3: Alex
B4: Currency | C4: $ | E4: Budget year | F4: 2026 | H4: Monthly income (for 50/30/20) | M4: Partner B name | N4: Sam
B6: INCOME SOURCES | D6: EXPENSE CATEGORIES | F6: ACCOUNTS | H6: CATEGORY | I6: 50/30/20 type | K6: all categories (dropdown)
B7: Salary | D7: Rent or Mortgage | F7: Checking | H7: =IF(D7="","",D7) | I7: needs | K7: Salary | M7: Paid-by options | N7: =IF($N$3="","Partner A",$N$3)
B8: Side income | D8: Utilities | F8: Savings | H8: =IF(D8="","",D8) | I8: needs | K8: Side income | N8: =IF($N$4="","Partner B",$N$4)
B9: Other income | D9: Groceries | F9: Cash | H9: =IF(D9="","",D9) | I9: needs | K9: Other income | N9: Joint
D10: Transport | F10: Credit Card | H10: =IF(D10="","",D10) | I10: needs | K10: Rent or Mortgage
D11: Dining out | H11: =IF(D11="","",D11) | I11: wants | K11: Utilities | M11: Partner A income /mo | N11: 5200
D12: Subscriptions | H12: =IF(D12="","",D12) | I12: wants | K12: Groceries | M12: Partner B income /mo | N12: 3800
D13: Health | H13: =IF(D13="","",D13) | I13: needs | K13: Transport | M13: Split mode | N13: By income
D14: Insurance | H14: =IF(D14="","",D14) | I14: needs | K14: Dining out | M14: Custom Partner A % | N14: 50
D15: Phone and Internet | H15: =IF(D15="","",D15) | I15: needs | K15: Subscriptions
D16: Shopping | H16: =IF(D16="","",D16) | I16: wants | K16: Health | M16: Partner A share | N16: =IF(N13="50/50",0.5,IF(N13="By income",IF((N11+N12)=0,0.5,N11/(N11+N12)),IF(N13="Custom",N14/100,0.5)))
D17: Fun and Leisure | H17: =IF(D17="","",D17) | I17: wants | K17: Insurance | M17: Partner B share | N17: =1-N16
D18: Gifts | H18: =IF(D18="","",D18) | I18: wants | K18: Phone and Internet
D19: Savings | H19: =IF(D19="","",D19) | I19: savings | K19: Shopping
D20: Debt | H20: =IF(D20="","",D20) | I20: needs | K20: Fun and Leisure
K21: Gifts
K22: Savings
K23: Debt
K24: =IF('Savings & Net Worth'!A6="","",'Savings & Net Worth'!A6)
K25: =IF('Savings & Net Worth'!A7="","",'Savings & Net Worth'!A7)
K26: =IF('Savings & Net Worth'!A8="","",'Savings & Net Worth'!A8)
K27: =IF('Savings & Net Worth'!A9="","",'Savings & Net Worth'!A9)
K28: =IF('Savings & Net Worth'!A10="","",'Savings & Net Worth'!A10)
K29: =IF('Savings & Net Worth'!A11="","",'Savings & Net Worth'!A11)
K30: =IF('Savings & Net Worth'!A12="","",'Savings & Net Worth'!A12)
K31: =IF('Savings & Net Worth'!A13="","",'Savings & Net Worth'!A13)
K34: helper — you can hide columns H:K

Sheet Transactions
A1: Transactions
A2: Log every income and expense once, and mark who paid. The year, months and split fill in automatically.
A4: Date | B4: Type | C4: Category | D4: Account | E4: Amount | F4: Paid by | G4: Share | H4: Note | I4: Month# | J4: Year# | K4: 50/30/20
A5: 46023 | B5: Income | C5: Salary | D5: Checking | E5: 5200 | F5: Alex | G5: Personal | H5: Monthly pay | I5: =IF($A5="","",MONTH($A5)) | J5: =IF($A5="","",YEAR($A5)) | K5: =IFERROR(INDEX(Setup!$I$7:$I$22,MATCH($C5,Setup!$D$7:$D$22,0)),"")
A6: 46023 | B6: Income | C6: Salary | D6: Checking | E6: 3800 | F6: Sam | G6: Personal | H6: Monthly pay | I6: =IF($A6="","",MONTH($A6)) | J6: =IF($A6="","",YEAR($A6)) | K6: =IFERROR(INDEX(Setup!$I$7:$I$22,MATCH($C6,Setup!$D$7:$D$22,0)),"")
A7: 46023 | B7: Expense | C7: Rent or Mortgage | D7: Checking | E7: 2400 | F7: Alex | G7: Shared | H7: Rent | I7: =IF($A7="","",MONTH($A7)) | J7: =IF($A7="","",YEAR($A7)) | K7: =IFERROR(INDEX(Setup!$I$7:$I$22,MATCH($C7,Setup!$D$7:$D$22,0)),"")
A8: 46024 | B8: Transfer | C8: Emergency Fund | D8: Savings | E8: 850 | F8: Joint | G8: Shared | H8: Auto transfer | I8: =IF($A8="","",MONTH($A8)) | J8: =IF($A8="","",YEAR($A8)) | K8: =IFERROR(INDEX(Setup!$I$7:$I$22,MATCH($C8,Setup!$D$7:$D$22,0)),"")
A9: 46024 | B9: Transfer | C9: Holiday Fund | D9: Savings | E9: 420 | F9: Joint | G9: Shared | H9: Auto transfer | I9: =IF($A9="","",MONTH($A9)) | J9: =IF($A9="","",YEAR($A9)) | K9: =IFERROR(INDEX(Setup!$I$7:$I$22,MATCH($C9,Setup!$D$7:$D$22,0)),"")
A10: 46024 | B10: Transfer | C10: New Car | D10: Savings | E10: 610 | F10: Joint | G10: Shared | H10: Auto transfer | I10: =IF($A10="","",MONTH($A10)) | J10: =IF($A10="","",YEAR($A10)) | K10: =IFERROR(INDEX(Setup!$I$7:$I$22,MATCH($C10,Setup!$D$7:$D$22,0)),"")
A11: 46025 | B11: Expense | C11: Insurance | D11: Checking | E11: 240 | F11: Joint | G11: Shared | H11: Home + car | I11: =IF($A11="","",MONTH($A11)) | J11: =IF($A11="","",YEAR($A11)) | K11: =IFERROR(INDEX(Setup!$I$7:$I$22,MATCH($C11,Setup!$D$7:$D$22,0)),"")
A12: 46026 | B12: Expense | C12: Utilities | D12: Checking | E12: 254.54 | F12: Sam | G12: Shared | H12: Electric and gas | I12: =IF($A12="","",MONTH($A12)) | J12: =IF($A12="","",YEAR($A12)) | K12: =IFERROR(INDEX(Setup!$I$7:$I$22,MATCH($C12,Setup!$D$7:$D$22,0)),"")
A13: 46028 | B13: Expense | C13: Groceries | D13: Credit Card | E13: 317.36 | F13: Sam | G13: Shared | H13: Weekly shop | I13: =IF($A13="","",MONTH($A13)) | J13: =IF($A13="","",YEAR($A13)) | K13: =IFERROR(INDEX(Setup!$I$7:$I$22,MATCH($C13,Setup!$D$7:$D$22,0)),"")
A14: 46029 | B14: Expense | C14: Subscriptions | D14: Credit Card | E14: 46.99 | F14: Alex | G14: Shared | H14: Streaming + cloud | I14: =IF($A14="","",MONTH($A14)) | J14: =IF($A14="","",YEAR($A14)) | K14: =IFERROR(INDEX(Setup!$I$7:$I$22,MATCH($C14,Setup!$D$7:$D$22,0)),"")
A15: 46030 | B15: Expense | C15: Phone and Internet | D15: Checking | E15: 110 | F15: Sam | G15: Shared | H15: Fibre + mobiles | I15: =IF($A15="","",MONTH($A15)) | J15: =IF($A15="","",YEAR($A15)) | K15: =IFERROR(INDEX(Setup!$I$7:$I$22,MATCH($C15,Setup!$D$7:$D$22,0)),"")
A16: 46031 | B16: Expense | C16: Transport | D16: Credit Card | E16: 177.94 | F16: Alex | G16: Shared | H16: Fuel and transit | I16: =IF($A16="","",MONTH($A16)) | J16: =IF($A16="","",YEAR($A16)) | K16: =IFERROR(INDEX(Setup!$I$7:$I$22,MATCH($C16,Setup!$D$7:$D$22,0)),"")
... A273: 46382 | B273: Expense | C273: Fun and Leisure | D273: Credit Card | E273: 640 | F273: Joint | G273: Shared | H273: Weekend away | I273: =IF($A273="","",MONTH($A273)) | J273: =IF($A273="","",YEAR($A273)) | K273: =IFERROR(INDEX(Setup!$I$7:$I$22,MATCH($C273,Setup!$D$7:$D$22,0)),"")
I274: =IF($A274="","",MONTH($A274)) | J274: =IF($A274="","",YEAR($A274)) | K274: =IFERROR(INDEX(Setup!$I$7:$I$22,MATCH($C274,Setup!$D$7:$D$22,0)),"")
I275: =IF($A275="","",MONTH($A275)) | J275: =IF($A275="","",YEAR($A275)) | K275: =IFERROR(INDEX(Setup!$I$7:$I$22,MATCH($C275,Setup!$D$7:$D$22,0)),"")
I276: =IF($A276="","",MONTH($A276)) | J276: =IF($A276="","",YEAR($A276)) | K276: =IFERROR(INDEX(Setup!$I$7:$I$22,MATCH($C276,Setup!$D$7:$D$22,0)),"")
I277: =IF($A277="","",MONTH($A277)) | J277: =IF($A277="","",YEAR($A277)) | K277: =IFERROR(INDEX(Setup!$I$7:$I$22,MATCH($C277,Setup!$D$7:$D$22,0)),"")
I278: =IF($A278="","",MONTH($A278)) | J278: =IF($A278="","",YEAR($A278)) | K278: =IFERROR(INDEX(Setup!$I$7:$I$22,MATCH($C278,Setup!$D$7:$D$22,0)),"")
I279: =IF($A279="","",MONTH($A279)) | J279: =IF($A279="","",YEAR($A279)) | K279: =IFERROR(INDEX(Setup!$I$7:$I$22,MATCH($C279,Setup!$D$7:$D$22,0)),"")
I280: =IF($A280="","",MONTH($A280)) | J280: =IF($A280="","",YEAR($A280)) | K280: =IFERROR(INDEX(Setup!$I$7:$I$22,MATCH($C280,Setup!$D$7:$D$22,0)),"")
I281: =IF($A281="","",MONTH($A281)) | J281: =IF($A281="","",YEAR($A281)) | K281: =IFERROR(INDEX(Setup!$I$7:$I$22,MATCH($C281,Setup!$D$7:$D$22,0)),"")
I282: =IF($A282="","",MONTH($A282)) | J282: =IF($A282="","",YEAR($A282)) | K282: =IFERROR(INDEX(Setup!$I$7:$I$22,MATCH($C282,Setup!$D$7:$D$22,0)),"")
I283: =IF($A283="","",MONTH($A283)) | J283: =IF($A283="","",YEAR($A283)) | K283: =IFERROR(INDEX(Setup!$I$7:$I$22,MATCH($C283,Setup!$D$7:$D$22,0)),"")
I284: =IF($A284="","",MONTH($A284)) | J284: =IF($A284="","",YEAR($A284)) | K284: =IFERROR(INDEX(Setup!$I$7:$I$22,MATCH($C284,Setup!$D$7:$D$22,0)),"")
I285: =IF($A285="","",MONTH($A285)) | J285: =IF($A285="","",YEAR($A285)) | K285: =IFERROR(INDEX(Setup!$I$7:$I$22,MATCH($C285,Setup!$D$7:$D$22,0)),"")
... I504: =IF($A504="","",MONTH($A504)) | J504: =IF($A504="","",YEAR($A504)) | K504: =IFERROR(INDEX(Setup!$I$7:$I$22,MATCH($C504,Setup!$D$7:$D$22,0)),"")

Sheet Annual Dashboard
A1: Annual Dashboard
A2: Your whole year at a glance. Nothing to fill in — it reads your Transactions.
A4: Year | B4: =Setup!$F$4
B6: INCOME (YEAR) | E6: EXPENSES | H6: SAVED | K6: NET
B7: =SUMIFS(Transactions!$E$5:$E$504,Transactions!$B$5:$B$504,"Income",Transactions!$J$5:$J$504,Setup!$F$4) | E7: =SUMIFS(Transactions!$E$5:$E$504,Transactions!$B$5:$B$504,"Expense",Transactions!$J$5:$J$504,Setup!$F$4) | H7: =SUMIFS(Transactions!$E$5:$E$504,Transactions!$B$5:$B$504,"Transfer",Transactions!$J$5:$J$504,Setup!$F$4) | K7: =B7-E7-H7
A10: MONTH | B10: Jan | C10: Feb | D10: Mar | E10: Apr | F10: May | G10: Jun | H10: Jul | I10: Aug | J10: Sep | K10: Oct | L10: Nov | M10: Dec | N10: TOTAL
A11: Income | B11: =SUMIFS(Transactions!$E$5:$E$504,Transactions!$B$5:$B$504,"Income",Transactions!$I$5:$I$504,1,Transactions!$J$5:$J$504,Setup!$F$4) | C11: =SUMIFS(Transactions!$E$5:$E$504,Transactions!$B$5:$B$504,"Income",Transactions!$I$5:$I$504,2,Transactions!$J$5:$J$504,Setup!$F$4) | D11: =SUMIFS(Transactions!$E$5:$E$504,Transactions!$B$5:$B$504,"Income",Transactions!$I$5:$I$504,3,Transactions!$J$5:$J$504,Setup!$F$4) | E11: =SUMIFS(Transactions!$E$5:$E$504,Transactions!$B$5:$B$504,"Income",Transactions!$I$5:$I$504,4,Transactions!$J$5:$J$504,Setup!$F$4) | F11: =SUMIFS(Transactions!$E$5:$E$504,Transactions!$B$5:$B$504,"Income",Transactions!$I$5:$I$504,5,Transactions!$J$5:$J$504,Setup!$F$4) | G11: =SUMIFS(Transactions!$E$5:$E$504,Transactions!$B$5:$B$504,"Income",Transactions!$I$5:$I$504,6,Transactions!$J$5:$J$504,Setup!$F$4) | H11: =SUMIFS(Transactions!$E$5:$E$504,Transactions!$B$5:$B$504,"Income",Transactions!$I$5:$I$504,7,Transactions!$J$5:$J$504,Setup!$F$4) | I11: =SUMIFS(Transactions!$E$5:$E$504,Transactions!$B$5:$B$504,"Income",Transactions!$I$5:$I$504,8,Transactions!$J$5:$J$504,Setup!$F$4) | J11: =SUMIFS(Transactions!$E$5:$E$504,Transactions!$B$5:$B$504,"Income",Transactions!$I$5:$I$504,9,Transactions!$J$5:$J$504,Setup!$F$4) | K11: =SUMIFS(Transactions!$E$5:$E$504,Transactions!$B$5:$B$504,"Income",Transactions!$I$5:$I$504,10,Transactions!$J$5:$J$504,Setup!$F$4) | L11: =SUMIFS(Transactions!$E$5:$E$504,Transactions!$B$5:$B$504,"Income",Transactions!$I$5:$I$504,11,Transactions!$J$5:$J$504,Setup!$F$4) | M11: =SUMIFS(Transactions!$E$5:$E$504,Transactions!$B$5:$B$504,"Income",Transactions!$I$5:$I$504,12,Transactions!$J$5:$J$504,Setup!$F$4) | N11: =SUM(B11:M11)
A12: Expenses | B12: =SUMIFS(Transactions!$E$5:$E$504,Transactions!$B$5:$B$504,"Expense",Transactions!$I$5:$I$504,1,Transactions!$J$5:$J$504,Setup!$F$4) | C12: =SUMIFS(Transactions!$E$5:$E$504,Transactions!$B$5:$B$504,"Expense",Transactions!$I$5:$I$504,2,Transactions!$J$5:$J$504,Setup!$F$4) | D12: =SUMIFS(Transactions!$E$5:$E$504,Transactions!$B$5:$B$504,"Expense",Transactions!$I$5:$I$504,3,Transactions!$J$5:$J$504,Setup!$F$4) | E12: =SUMIFS(Transactions!$E$5:$E$504,Transactions!$B$5:$B$504,"Expense",Transactions!$I$5:$I$504,4,Transactions!$J$5:$J$504,Setup!$F$4) | F12: =SUMIFS(Transactions!$E$5:$E$504,Transactions!$B$5:$B$504,"Expense",Transactions!$I$5:$I$504,5,Transactions!$J$5:$J$504,Setup!$F$4) | G12: =SUMIFS(Transactions!$E$5:$E$504,Transactions!$B$5:$B$504,"Expense",Transactions!$I$5:$I$504,6,Transactions!$J$5:$J$504,Setup!$F$4) | H12: =SUMIFS(Transactions!$E$5:$E$504,Transactions!$B$5:$B$504,"Expense",Transactions!$I$5:$I$504,7,Transactions!$J$5:$J$504,Setup!$F$4) | I12: =SUMIFS(Transactions!$E$5:$E$504,Transactions!$B$5:$B$504,"Expense",Transactions!$I$5:$I$504,8,Transactions!$J$5:$J$504,Setup!$F$4) | J12: =SUMIFS(Transactions!$E$5:$E$504,Transactions!$B$5:$B$504,"Expense",Transactions!$I$5:$I$504,9,Transactions!$J$5:$J$504,Setup!$F$4) | K12: =SUMIFS(Transactions!$E$5:$E$504,Transactions!$B$5:$B$504,"Expense",Transactions!$I$5:$I$504,10,Transactions!$J$5:$J$504,Setup!$F$4) | L12: =SUMIFS(Transactions!$E$5:$E$504,Transactions!$B$5:$B$504,"Expense",Transactions!$I$5:$I$504,11,Transactions!$J$5:$J$504,Setup!$F$4) | M12: =SUMIFS(Transactions!$E$5:$E$504,Transactions!$B$5:$B$504,"Expense",Transactions!$I$5:$I$504,12,Transactions!$J$5:$J$504,Setup!$F$4) | N12: =SUM(B12:M12)
A13: Saved | B13: =SUMIFS(Transactions!$E$5:$E$504,Transactions!$B$5:$B$504,"Transfer",Transactions!$I$5:$I$504,1,Transactions!$J$5:$J$504,Setup!$F$4) | C13: =SUMIFS(Transactions!$E$5:$E$504,Transactions!$B$5:$B$504,"Transfer",Transactions!$I$5:$I$504,2,Transactions!$J$5:$J$504,Setup!$F$4) | D13: =SUMIFS(Transactions!$E$5:$E$504,Transactions!$B$5:$B$504,"Transfer",Transactions!$I$5:$I$504,3,Transactions!$J$5:$J$504,Setup!$F$4) | E13: =SUMIFS(Transactions!$E$5:$E$504,Transactions!$B$5:$B$504,"Transfer",Transactions!$I$5:$I$504,4,Transactions!$J$5:$J$504,Setup!$F$4) | F13: =SUMIFS(Transactions!$E$5:$E$504,Transactions!$B$5:$B$504,"Transfer",Transactions!$I$5:$I$504,5,Transactions!$J$5:$J$504,Setup!$F$4) | G13: =SUMIFS(Transactions!$E$5:$E$504,Transactions!$B$5:$B$504,"Transfer",Transactions!$I$5:$I$504,6,Transactions!$J$5:$J$504,Setup!$F$4) | H13: =SUMIFS(Transactions!$E$5:$E$504,Transactions!$B$5:$B$504,"Transfer",Transactions!$I$5:$I$504,7,Transactions!$J$5:$J$504,Setup!$F$4) | I13: =SUMIFS(Transactions!$E$5:$E$504,Transactions!$B$5:$B$504,"Transfer",Transactions!$I$5:$I$504,8,Transactions!$J$5:$J$504,Setup!$F$4) | J13: =SUMIFS(Transactions!$E$5:$E$504,Transactions!$B$5:$B$504,"Transfer",Transactions!$I$5:$I$504,9,Transactions!$J$5:$J$504,Setup!$F$4) | K13: =SUMIFS(Transactions!$E$5:$E$504,Transactions!$B$5:$B$504,"Transfer",Transactions!$I$5:$I$504,10,Transactions!$J$5:$J$504,Setup!$F$4) | L13: =SUMIFS(Transactions!$E$5:$E$504,Transactions!$B$5:$B$504,"Transfer",Transactions!$I$5:$I$504,11,Transactions!$J$5:$J$504,Setup!$F$4) | M13: =SUMIFS(Transactions!$E$5:$E$504,Transactions!$B$5:$B$504,"Transfer",Transactions!$I$5:$I$504,12,Transactions!$J$5:$J$504,Setup!$F$4) | N13: =SUM(B13:M13)
A14: Net | B14: =B11-B12-B13 | C14: =C11-C12-C13 | D14: =D11-D12-D13 | E14: =E11-E12-E13 | F14: =F11-F12-F13 | G14: =G11-G12-G13 | H14: =H11-H12-H13 | I14: =I11-I12-I13 | ... M14: =M11-M12-M13 | N14: =SUM(B14:M14)
A16: SPENDING BY CATEGORY | B16: Jan | C16: Feb | D16: Mar | E16: Apr | F16: May | G16: Jun | H16: Jul | I16: Aug | J16: Sep | K16: Oct | L16: Nov | M16: Dec | N16: TOTAL | O16: AVG/mo
A17: =IF(Setup!D7="","",Setup!D7) | B17: =IF($A17="","",SUMIFS(Transactions!$E$5:$E$504,Transactions!$B$5:$B$504,"Expense",Transactions!$C$5:$C$504,$A17,Transactions!$I$5:$I$504,1,Transactions!$J$5:$J$504,Setup!$F$4)) | C17: =IF($A17="","",SUMIFS(Transactions!$E$5:$E$504,Transactions!$B$5:$B$504,"Expense",Transactions!$C$5:$C$504,$A17,Transactions!$I$5:$I$504,2,Transactions!$J$5:$J$504,Setup!$F$4)) | D17: =IF($A17="","",SUMIFS(Transactions!$E$5:$E$504,Transactions!$B$5:$B$504,"Expense",Transactions!$C$5:$C$504,$A17,Transactions!$I$5:$I$504,3,Transactions!$J$5:$J$504,Setup!$F$4)) | E17: =IF($A17="","",SUMIFS(Transactions!$E$5:$E$504,Transactions!$B$5:$B$504,"Expense",Transactions!$C$5:$C$504,$A17,Transactions!$I$5:$I$504,4,Transactions!$J$5:$J$504,Setup!$F$4)) | F17: =IF($A17="","",SUMIFS(Transactions!$E$5:$E$504,Transactions!$B$5:$B$504,"Expense",Transactions!$C$5:$C$504,$A17,Transactions!$I$5:$I$504,5,Transactions!$J$5:$J$504,Setup!$F$4)) | G17: =IF($A17="","",SUMIFS(Transactions!$E$5:$E$504,Transactions!$B$5:$B$504,"Expense",Transactions!$C$5:$C$504,$A17,Transactions!$I$5:$I$504,6,Transactions!$J$5:$J$504,Setup!$F$4)) | H17: =IF($A17="","",SUMIFS(Transactions!$E$5:$E$504,Transactions!$B$5:$B$504,"Expense",Transactions!$C$5:$C$504,$A17,Transactions!$I$5:$I$504,7,Transactions!$J$5:$J$504,Setup!$F$4)) | I17: =IF($A17="","",SUMIFS(Transactions!$E$5:$E$504,Transactions!$B$5:$B$504,"Expense",Transactions!$C$5:$C$504,$A17,Transactions!$I$5:$I$504,8,Transactions!$J$5:$J$504,Setup!$F$4)) | J17: =IF($A17="","",SUMIFS(Transactions!$E$5:$E$504,Transactions!$B$5:$B$504,"Expense",Transactions!$C$5:$C$504,$A17,Transactions!$I$5:$I$504,9,Transactions!$J$5:$J$504,Setup!$F$4)) | K17: =IF($A17="","",SUMIFS(Transactions!$E$5:$E$504,Transactions!$B$5:$B$504,"Expense",Transactions!$C$5:$C$504,$A17,Transactions!$I$5:$I$504,10,Transactions!$J$5:$J$504,Setup!$F$4)) | L17: =IF($A17="","",SUMIFS(Transactions!$E$5:$E$504,Transactions!$B$5:$B$504,"Expense",Transactions!$C$5:$C$504,$A17,Transactions!$I$5:$I$504,11,Transactions!$J$5:$J$504,Setup!$F$4)) | M17: =IF($A17="","",SUMIFS(Transactions!$E$5:$E$504,Transactions!$B$5:$B$504,"Expense",Transactions!$C$5:$C$504,$A17,Transactions!$I$5:$I$504,12,Transactions!$J$5:$J$504,Setup!$F$4)) | N17: =IF($A17="","",SUM(B17:M17)) | O17: =IF($A17="","",N17/12)
A18: =IF(Setup!D8="","",Setup!D8) | B18: =IF($A18="","",SUMIFS(Transactions!$E$5:$E$504,Transactions!$B$5:$B$504,"Expense",Transactions!$C$5:$C$504,$A18,Transactions!$I$5:$I$504,1,Transactions!$J$5:$J$504,Setup!$F$4)) | C18: =IF($A18="","",SUMIFS(Transactions!$E$5:$E$504,Transactions!$B$5:$B$504,"Expense",Transactions!$C$5:$C$504,$A18,Transactions!$I$5:$I$504,2,Transactions!$J$5:$J$504,Setup!$F$4)) | D18: =IF($A18="","",SUMIFS(Transactions!$E$5:$E$504,Transactions!$B$5:$B$504,"Expense",Transactions!$C$5:$C$504,$A18,Transactions!$I$5:$I$504,3,Transactions!$J$5:$J$504,Setup!$F$4)) | E18: =IF($A18="","",SUMIFS(Transactions!$E$5:$E$504,Transactions!$B$5:$B$504,"Expense",Transactions!$C$5:$C$504,$A18,Transactions!$I$5:$I$504,4,Transactions!$J$5:$J$504,Setup!$F$4)) | F18: =IF($A18="","",SUMIFS(Transactions!$E$5:$E$504,Transactions!$B$5:$B$504,"Expense",Transactions!$C$5:$C$504,$A18,Transactions!$I$5:$I$504,5,Transactions!$J$5:$J$504,Setup!$F$4)) | G18: =IF($A18="","",SUMIFS(Transactions!$E$5:$E$504,Transactions!$B$5:$B$504,"Expense",Transactions!$C$5:$C$504,$A18,Transactions!$I$5:$I$504,6,Transactions!$J$5:$J$504,Setup!$F$4)) | H18: =IF($A18="","",SUMIFS(Transactions!$E$5:$E$504,Transactions!$B$5:$B$504,"Expense",Transactions!$C$5:$C$504,$A18,Transactions!$I$5:$I$504,7,Transactions!$J$5:$J$504,Setup!$F$4)) | I18: =IF($A18="","",SUMIFS(Transactions!$E$5:$E$504,Transactions!$B$5:$B$504,"Expense",Transactions!$C$5:$C$504,$A18,Transactions!$I$5:$I$504,8,Transactions!$J$5:$J$504,Setup!$F$4)) | J18: =IF($A18="","",SUMIFS(Transactions!$E$5:$E$504,Transactions!$B$5:$B$504,"Expense",Transactions!$C$5:$C$504,$A18,Transactions!$I$5:$I$504,9,Transactions!$J$5:$J$504,Setup!$F$4)) | K18: =IF($A18="","",SUMIFS(Transactions!$E$5:$E$504,Transactions!$B$5:$B$504,"Expense",Transactions!$C$5:$C$504,$A18,Transactions!$I$5:$I$504,10,Transactions!$J$5:$J$504,Setup!$F$4)) | L18: =IF($A18="","",SUMIFS(Transactions!$E$5:$E$504,Transactions!$B$5:$B$504,"Expense",Transactions!$C$5:$C$504,$A18,Transactions!$I$5:$I$504,11,Transactions!$J$5:$J$504,Setup!$F$4)) | M18: =IF($A18="","",SUMIFS(Transactions!$E$5:$E$504,Transactions!$B$5:$B$504,"Expense",Transactions!$C$5:$C$504,$A18,Transactions!$I$5:$I$504,12,Transactions!$J$5:$J$504,Setup!$F$4)) | N18: =IF($A18="","",SUM(B18:M18)) | O18: =IF($A18="","",N18/12)
A19: =IF(Setup!D9="","",Setup!D9) | B19: =IF($A19="","",SUMIFS(Transactions!$E$5:$E$504,Transactions!$B$5:$B$504,"Expense",Transactions!$C$5:$C$504,$A19,Transactions!$I$5:$I$504,1,Transactions!$J$5:$J$504,Setup!$F$4)) | C19: =IF($A19="","",SUMIFS(Transactions!$E$5:$E$504,Transactions!$B$5:$B$504,"Expense",Transactions!$C$5:$C$504,$A19,Transactions!$I$5:$I$504,2,Transactions!$J$5:$J$504,Setup!$F$4)) | D19: =IF($A19="","",SUMIFS(Transactions!$E$5:$E$504,Transactions!$B$5:$B$504,"Expense",Transactions!$C$5:$C$504,$A19,Transactions!$I$5:$I$504,3,Transactions!$J$5:$J$504,Setup!$F$4)) | E19: =IF($A19="","",SUMIFS(Transactions!$E$5:$E$504,Transactions!$B$5:$B$504,"Expense",Transactions!$C$5:$C$504,$A19,Transactions!$I$5:$I$504,4,Transactions!$J$5:$J$504,Setup!$F$4)) | F19: =IF($A19="","",SUMIFS(Transactions!$E$5:$E$504,Transactions!$B$5:$B$504,"Expense",Transactions!$C$5:$C$504,$A19,Transactions!$I$5:$I$504,5,Transactions!$J$5:$J$504,Setup!$F$4)) | G19: =IF($A19="","",SUMIFS(Transactions!$E$5:$E$504,Transactions!$B$5:$B$504,"Expense",Transactions!$C$5:$C$504,$A19,Transactions!$I$5:$I$504,6,Transactions!$J$5:$J$504,Setup!$F$4)) | H19: =IF($A19="","",SUMIFS(Transactions!$E$5:$E$504,Transactions!$B$5:$B$504,"Expense",Transactions!$C$5:$C$504,$A19,Transactions!$I$5:$I$504,7,Transactions!$J$5:$J$504,Setup!$F$4)) | I19: =IF($A19="","",SUMIFS(Transactions!$E$5:$E$504,Transactions!$B$5:$B$504,"Expense",Transactions!$C$5:$C$504,$A19,Transactions!$I$5:$I$504,8,Transactions!$J$5:$J$504,Setup!$F$4)) | J19: =IF($A19="","",SUMIFS(Transactions!$E$5:$E$504,Transactions!$B$5:$B$504,"Expense",Transactions!$C$5:$C$504,$A19,Transactions!$I$5:$I$504,9,Transactions!$J$5:$J$504,Setup!$F$4)) | K19: =IF($A19="","",SUMIFS(Transactions!$E$5:$E$504,Transactions!$B$5:$B$504,"Expense",Transactions!$C$5:$C$504,$A19,Transactions!$I$5:$I$504,10,Transactions!$J$5:$J$504,Setup!$F$4)) | L19: =IF($A19="","",SUMIFS(Transactions!$E$5:$E$504,Transactions!$B$5:$B$504,"Expense",Transactions!$C$5:$C$504,$A19,Transactions!$I$5:$I$504,11,Transactions!$J$5:$J$504,Setup!$F$4)) | M19: =IF($A19="","",SUMIFS(Transactions!$E$5:$E$504,Transactions!$B$5:$B$504,"Expense",Transactions!$C$5:$C$504,$A19,Transactions!$I$5:$I$504,12,Transactions!$J$5:$J$504,Setup!$F$4)) | N19: =IF($A19="","",SUM(B19:M19)) | O19: =IF($A19="","",N19/12)
A20: =IF(Setup!D10="","",Setup!D10) | B20: =IF($A20="","",SUMIFS(Transactions!$E$5:$E$504,Transactions!$B$5:$B$504,"Expense",Transactions!$C$5:$C$504,$A20,Transactions!$I$5:$I$504,1,Transactions!$J$5:$J$504,Setup!$F$4)) | C20: =IF($A20="","",SUMIFS(Transactions!$E$5:$E$504,Transactions!$B$5:$B$504,"Expense",Transactions!$C$5:$C$504,$A20,Transactions!$I$5:$I$504,2,Transactions!$J$5:$J$504,Setup!$F$4)) | D20: =IF($A20="","",SUMIFS(Transactions!$E$5:$E$504,Transactions!$B$5:$B$504,"Expense",Transactions!$C$5:$C$504,$A20,Transactions!$I$5:$I$504,3,Transactions!$J$5:$J$504,Setup!$F$4)) | E20: =IF($A20="","",SUMIFS(Transactions!$E$5:$E$504,Transactions!$B$5:$B$504,"Expense",Transactions!$C$5:$C$504,$A20,Transactions!$I$5:$I$504,4,Transactions!$J$5:$J$504,Setup!$F$4)) | F20: =IF($A20="","",SUMIFS(Transactions!$E$5:$E$504,Transactions!$B$5:$B$504,"Expense",Transactions!$C$5:$C$504,$A20,Transactions!$I$5:$I$504,5,Transactions!$J$5:$J$504,Setup!$F$4)) | G20: =IF($A20="","",SUMIFS(Transactions!$E$5:$E$504,Transactions!$B$5:$B$504,"Expense",Transactions!$C$5:$C$504,$A20,Transactions!$I$5:$I$504,6,Transactions!$J$5:$J$504,Setup!$F$4)) | H20: =IF($A20="","",SUMIFS(Transactions!$E$5:$E$504,Transactions!$B$5:$B$504,"Expense",Transactions!$C$5:$C$504,$A20,Transactions!$I$5:$I$504,7,Transactions!$J$5:$J$504,Setup!$F$4)) | I20: =IF($A20="","",SUMIFS(Transactions!$E$5:$E$504,Transactions!$B$5:$B$504,"Expense",Transactions!$C$5:$C$504,$A20,Transactions!$I$5:$I$504,8,Transactions!$J$5:$J$504,Setup!$F$4)) | J20: =IF($A20="","",SUMIFS(Transactions!$E$5:$E$504,Transactions!$B$5:$B$504,"Expense",Transactions!$C$5:$C$504,$A20,Transactions!$I$5:$I$504,9,Transactions!$J$5:$J$504,Setup!$F$4)) | K20: =IF($A20="","",SUMIFS(Transactions!$E$5:$E$504,Transactions!$B$5:$B$504,"Expense",Transactions!$C$5:$C$504,$A20,Transactions!$I$5:$I$504,10,Transactions!$J$5:$J$504,Setup!$F$4)) | L20: =IF($A20="","",SUMIFS(Transactions!$E$5:$E$504,Transactions!$B$5:$B$504,"Expense",Transactions!$C$5:$C$504,$A20,Transactions!$I$5:$I$504,11,Transactions!$J$5:$J$504,Setup!$F$4)) | M20: =IF($A20="","",SUMIFS(Transactions!$E$5:$E$504,Transactions!$B$5:$B$504,"Expense",Transactions!$C$5:$C$504,$A20,Transactions!$I$5:$I$504,12,Transactions!$J$5:$J$504,Setup!$F$4)) | N20: =IF($A20="","",SUM(B20:M20)) | O20: =IF($A20="","",N20/12)
A21: =IF(Setup!D11="","",Setup!D11) | B21: =IF($A21="","",SUMIFS(Transactions!$E$5:$E$504,Transactions!$B$5:$B$504,"Expense",Transactions!$C$5:$C$504,$A21,Transactions!$I$5:$I$504,1,Transactions!$J$5:$J$504,Setup!$F$4)) | C21: =IF($A21="","",SUMIFS(Transactions!$E$5:$E$504,Transactions!$B$5:$B$504,"Expense",Transactions!$C$5:$C$504,$A21,Transactions!$I$5:$I$504,2,Transactions!$J$5:$J$504,Setup!$F$4)) | D21: =IF($A21="","",SUMIFS(Transactions!$E$5:$E$504,Transactions!$B$5:$B$504,"Expense",Transactions!$C$5:$C$504,$A21,Transactions!$I$5:$I$504,3,Transactions!$J$5:$J$504,Setup!$F$4)) | E21: =IF($A21="","",SUMIFS(Transactions!$E$5:$E$504,Transactions!$B$5:$B$504,"Expense",Transactions!$C$5:$C$504,$A21,Transactions!$I$5:$I$504,4,Transactions!$J$5:$J$504,Setup!$F$4)) | F21: =IF($A21="","",SUMIFS(Transactions!$E$5:$E$504,Transactions!$B$5:$B$504,"Expense",Transactions!$C$5:$C$504,$A21,Transactions!$I$5:$I$504,5,Transactions!$J$5:$J$504,Setup!$F$4)) | G21: =IF($A21="","",SUMIFS(Transactions!$E$5:$E$504,Transactions!$B$5:$B$504,"Expense",Transactions!$C$5:$C$504,$A21,Transactions!$I$5:$I$504,6,Transactions!$J$5:$J$504,Setup!$F$4)) | H21: =IF($A21="","",SUMIFS(Transactions!$E$5:$E$504,Transactions!$B$5:$B$504,"Expense",Transactions!$C$5:$C$504,$A21,Transactions!$I$5:$I$504,7,Transactions!$J$5:$J$504,Setup!$F$4)) | I21: =IF($A21="","",SUMIFS(Transactions!$E$5:$E$504,Transactions!$B$5:$B$504,"Expense",Transactions!$C$5:$C$504,$A21,Transactions!$I$5:$I$504,8,Transactions!$J$5:$J$504,Setup!$F$4)) | J21: =IF($A21="","",SUMIFS(Transactions!$E$5:$E$504,Transactions!$B$5:$B$504,"Expense",Transactions!$C$5:$C$504,$A21,Transactions!$I$5:$I$504,9,Transactions!$J$5:$J$504,Setup!$F$4)) | K21: =IF($A21="","",SUMIFS(Transactions!$E$5:$E$504,Transactions!$B$5:$B$504,"Expense",Transactions!$C$5:$C$504,$A21,Transactions!$I$5:$I$504,10,Transactions!$J$5:$J$504,Setup!$F$4)) | L21: =IF($A21="","",SUMIFS(Transactions!$E$5:$E$504,Transactions!$B$5:$B$504,"Expense",Transactions!$C$5:$C$504,$A21,Transactions!$I$5:$I$504,11,Transactions!$J$5:$J$504,Setup!$F$4)) | M21: =IF($A21="","",SUMIFS(Transactions!$E$5:$E$504,Transactions!$B$5:$B$504,"Expense",Transactions!$C$5:$C$504,$A21,Transactions!$I$5:$I$504,12,Transactions!$J$5:$J$504,Setup!$F$4)) | N21: =IF($A21="","",SUM(B21:M21)) | O21: =IF($A21="","",N21/12)
A22: =IF(Setup!D12="","",Setup!D12) | B22: =IF($A22="","",SUMIFS(Transactions!$E$5:$E$504,Transactions!$B$5:$B$504,"Expense",Transactions!$C$5:$C$504,$A22,Transactions!$I$5:$I$504,1,Transactions!$J$5:$J$504,Setup!$F$4)) | C22: =IF($A22="","",SUMIFS(Transactions!$E$5:$E$504,Transactions!$B$5:$B$504,"Expense",Transactions!$C$5:$C$504,$A22,Transactions!$I$5:$I$504,2,Transactions!$J$5:$J$504,Setup!$F$4)) | D22: =IF($A22="","",SUMIFS(Transactions!$E$5:$E$504,Transactions!$B$5:$B$504,"Expense",Transactions!$C$5:$C$504,$A22,Transactions!$I$5:$I$504,3,Transactions!$J$5:$J$504,Setup!$F$4)) | E22: =IF($A22="","",SUMIFS(Transactions!$E$5:$E$504,Transactions!$B$5:$B$504,"Expense",Transactions!$C$5:$C$504,$A22,Transactions!$I$5:$I$504,4,Transactions!$J$5:$J$504,Setup!$F$4)) | F22: =IF($A22="","",SUMIFS(Transactions!$E$5:$E$504,Transactions!$B$5:$B$504,"Expense",Transactions!$C$5:$C$504,$A22,Transactions!$I$5:$I$504,5,Transactions!$J$5:$J$504,Setup!$F$4)) | G22: =IF($A22="","",SUMIFS(Transactions!$E$5:$E$504,Transactions!$B$5:$B$504,"Expense",Transactions!$C$5:$C$504,$A22,Transactions!$I$5:$I$504,6,Transactions!$J$5:$J$504,Setup!$F$4)) | H22: =IF($A22="","",SUMIFS(Transactions!$E$5:$E$504,Transactions!$B$5:$B$504,"Expense",Transactions!$C$5:$C$504,$A22,Transactions!$I$5:$I$504,7,Transactions!$J$5:$J$504,Setup!$F$4)) | I22: =IF($A22="","",SUMIFS(Transactions!$E$5:$E$504,Transactions!$B$5:$B$504,"Expense",Transactions!$C$5:$C$504,$A22,Transactions!$I$5:$I$504,8,Transactions!$J$5:$J$504,Setup!$F$4)) | J22: =IF($A22="","",SUMIFS(Transactions!$E$5:$E$504,Transactions!$B$5:$B$504,"Expense",Transactions!$C$5:$C$504,$A22,Transactions!$I$5:$I$504,9,Transactions!$J$5:$J$504,Setup!$F$4)) | K22: =IF($A22="","",SUMIFS(Transactions!$E$5:$E$504,Transactions!$B$5:$B$504,"Expense",Transactions!$C$5:$C$504,$A22,Transactions!$I$5:$I$504,10,Transactions!$J$5:$J$504,Setup!$F$4)) | L22: =IF($A22="","",SUMIFS(Transactions!$E$5:$E$504,Transactions!$B$5:$B$504,"Expense",Transactions!$C$5:$C$504,$A22,Transactions!$I$5:$I$504,11,Transactions!$J$5:$J$504,Setup!$F$4)) | M22: =IF($A22="","",SUMIFS(Transactions!$E$5:$E$504,Transactions!$B$5:$B$504,"Expense",Transactions!$C$5:$C$504,$A22,Transactions!$I$5:$I$504,12,Transactions!$J$5:$J$504,Setup!$F$4)) | N22: =IF($A22="","",SUM(B22:M22)) | O22: =IF($A22="","",N22/12)
A23: =IF(Setup!D13="","",Setup!D13) | B23: =IF($A23="","",SUMIFS(Transactions!$E$5:$E$504,Transactions!$B$5:$B$504,"Expense",Transactions!$C$5:$C$504,$A23,Transactions!$I$5:$I$504,1,Transactions!$J$5:$J$504,Setup!$F$4)) | C23: =IF($A23="","",SUMIFS(Transactions!$E$5:$E$504,Transactions!$B$5:$B$504,"Expense",Transactions!$C$5:$C$504,$A23,Transactions!$I$5:$I$504,2,Transactions!$J$5:$J$504,Setup!$F$4)) | D23: =IF($A23="","",SUMIFS(Transactions!$E$5:$E$504,Transactions!$B$5:$B$504,"Expense",Transactions!$C$5:$C$504,$A23,Transactions!$I$5:$I$504,3,Transactions!$J$5:$J$504,Setup!$F$4)) | E23: =IF($A23="","",SUMIFS(Transactions!$E$5:$E$504,Transactions!$B$5:$B$504,"Expense",Transactions!$C$5:$C$504,$A23,Transactions!$I$5:$I$504,4,Transactions!$J$5:$J$504,Setup!$F$4)) | F23: =IF($A23="","",SUMIFS(Transactions!$E$5:$E$504,Transactions!$B$5:$B$504,"Expense",Transactions!$C$5:$C$504,$A23,Transactions!$I$5:$I$504,5,Transactions!$J$5:$J$504,Setup!$F$4)) | G23: =IF($A23="","",SUMIFS(Transactions!$E$5:$E$504,Transactions!$B$5:$B$504,"Expense",Transactions!$C$5:$C$504,$A23,Transactions!$I$5:$I$504,6,Transactions!$J$5:$J$504,Setup!$F$4)) | H23: =IF($A23="","",SUMIFS(Transactions!$E$5:$E$504,Transactions!$B$5:$B$504,"Expense",Transactions!$C$5:$C$504,$A23,Transactions!$I$5:$I$504,7,Transactions!$J$5:$J$504,Setup!$F$4)) | I23: =IF($A23="","",SUMIFS(Transactions!$E$5:$E$504,Transactions!$B$5:$B$504,"Expense",Transactions!$C$5:$C$504,$A23,Transactions!$I$5:$I$504,8,Transactions!$J$5:$J$504,Setup!$F$4)) | J23: =IF($A23="","",SUMIFS(Transactions!$E$5:$E$504,Transactions!$B$5:$B$504,"Expense",Transactions!$C$5:$C$504,$A23,Transactions!$I$5:$I$504,9,Transactions!$J$5:$J$504,Setup!$F$4)) | K23: =IF($A23="","",SUMIFS(Transactions!$E$5:$E$504,Transactions!$B$5:$B$504,"Expense",Transactions!$C$5:$C$504,$A23,Transactions!$I$5:$I$504,10,Transactions!$J$5:$J$504,Setup!$F$4)) | L23: =IF($A23="","",SUMIFS(Transactions!$E$5:$E$504,Transactions!$B$5:$B$504,"Expense",Transactions!$C$5:$C$504,$A23,Transactions!$I$5:$I$504,11,Transactions!$J$5:$J$504,Setup!$F$4)) | M23: =IF($A23="","",SUMIFS(Transactions!$E$5:$E$504,Transactions!$B$5:$B$504,"Expense",Transactions!$C$5:$C$504,$A23,Transactions!$I$5:$I$504,12,Transactions!$J$5:$J$504,Setup!$F$4)) | N23: =IF($A23="","",SUM(B23:M23)) | O23: =IF($A23="","",N23/12)
A24: =IF(Setup!D14="","",Setup!D14) | B24: =IF($A24="","",SUMIFS(Transactions!$E$5:$E$504,Transactions!$B$5:$B$504,"Expense",Transactions!$C$5:$C$504,$A24,Transactions!$I$5:$I$504,1,Transactions!$J$5:$J$504,Setup!$F$4)) | C24: =IF($A24="","",SUMIFS(Transactions!$E$5:$E$504,Transactions!$B$5:$B$504,"Expense",Transactions!$C$5:$C$504,$A24,Transactions!$I$5:$I$504,2,Transactions!$J$5:$J$504,Setup!$F$4)) | D24: =IF($A24="","",SUMIFS(Transactions!$E$5:$E$504,Transactions!$B$5:$B$504,"Expense",Transactions!$C$5:$C$504,$A24,Transactions!$I$5:$I$504,3,Transactions!$J$5:$J$504,Setup!$F$4)) | E24: =IF($A24="","",SUMIFS(Transactions!$E$5:$E$504,Transactions!$B$5:$B$504,"Expense",Transactions!$C$5:$C$504,$A24,Transactions!$I$5:$I$504,4,Transactions!$J$5:$J$504,Setup!$F$4)) | F24: =IF($A24="","",SUMIFS(Transactions!$E$5:$E$504,Transactions!$B$5:$B$504,"Expense",Transactions!$C$5:$C$504,$A24,Transactions!$I$5:$I$504,5,Transactions!$J$5:$J$504,Setup!$F$4)) | G24: =IF($A24="","",SUMIFS(Transactions!$E$5:$E$504,Transactions!$B$5:$B$504,"Expense",Transactions!$C$5:$C$504,$A24,Transactions!$I$5:$I$504,6,Transactions!$J$5:$J$504,Setup!$F$4)) | H24: =IF($A24="","",SUMIFS(Transactions!$E$5:$E$504,Transactions!$B$5:$B$504,"Expense",Transactions!$C$5:$C$504,$A24,Transactions!$I$5:$I$504,7,Transactions!$J$5:$J$504,Setup!$F$4)) | I24: =IF($A24="","",SUMIFS(Transactions!$E$5:$E$504,Transactions!$B$5:$B$504,"Expense",Transactions!$C$5:$C$504,$A24,Transactions!$I$5:$I$504,8,Transactions!$J$5:$J$504,Setup!$F$4)) | J24: =IF($A24="","",SUMIFS(Transactions!$E$5:$E$504,Transactions!$B$5:$B$504,"Expense",Transactions!$C$5:$C$504,$A24,Transactions!$I$5:$I$504,9,Transactions!$J$5:$J$504,Setup!$F$4)) | K24: =IF($A24="","",SUMIFS(Transactions!$E$5:$E$504,Transactions!$B$5:$B$504,"Expense",Transactions!$C$5:$C$504,$A24,Transactions!$I$5:$I$504,10,Transactions!$J$5:$J$504,Setup!$F$4)) | L24: =IF($A24="","",SUMIFS(Transactions!$E$5:$E$504,Transactions!$B$5:$B$504,"Expense",Transactions!$C$5:$C$504,$A24,Transactions!$I$5:$I$504,11,Transactions!$J$5:$J$504,Setup!$F$4)) | M24: =IF($A24="","",SUMIFS(Transactions!$E$5:$E$504,Transactions!$B$5:$B$504,"Expense",Transactions!$C$5:$C$504,$A24,Transactions!$I$5:$I$504,12,Transactions!$J$5:$J$504,Setup!$F$4)) | N24: =IF($A24="","",SUM(B24:M24)) | O24: =IF($A24="","",N24/12)
A25: =IF(Setup!D15="","",Setup!D15) | B25: =IF($A25="","",SUMIFS(Transactions!$E$5:$E$504,Transactions!$B$5:$B$504,"Expense",Transactions!$C$5:$C$504,$A25,Transactions!$I$5:$I$504,1,Transactions!$J$5:$J$504,Setup!$F$4)) | C25: =IF($A25="","",SUMIFS(Transactions!$E$5:$E$504,Transactions!$B$5:$B$504,"Expense",Transactions!$C$5:$C$504,$A25,Transactions!$I$5:$I$504,2,Transactions!$J$5:$J$504,Setup!$F$4)) | D25: =IF($A25="","",SUMIFS(Transactions!$E$5:$E$504,Transactions!$B$5:$B$504,"Expense",Transactions!$C$5:$C$504,$A25,Transactions!$I$5:$I$504,3,Transactions!$J$5:$J$504,Setup!$F$4)) | E25: =IF($A25="","",SUMIFS(Transactions!$E$5:$E$504,Transactions!$B$5:$B$504,"Expense",Transactions!$C$5:$C$504,$A25,Transactions!$I$5:$I$504,4,Transactions!$J$5:$J$504,Setup!$F$4)) | F25: =IF($A25="","",SUMIFS(Transactions!$E$5:$E$504,Transactions!$B$5:$B$504,"Expense",Transactions!$C$5:$C$504,$A25,Transactions!$I$5:$I$504,5,Transactions!$J$5:$J$504,Setup!$F$4)) | G25: =IF($A25="","",SUMIFS(Transactions!$E$5:$E$504,Transactions!$B$5:$B$504,"Expense",Transactions!$C$5:$C$504,$A25,Transactions!$I$5:$I$504,6,Transactions!$J$5:$J$504,Setup!$F$4)) | H25: =IF($A25="","",SUMIFS(Transactions!$E$5:$E$504,Transactions!$B$5:$B$504,"Expense",Transactions!$C$5:$C$504,$A25,Transactions!$I$5:$I$504,7,Transactions!$J$5:$J$504,Setup!$F$4)) | I25: =IF($A25="","",SUMIFS(Transactions!$E$5:$E$504,Transactions!$B$5:$B$504,"Expense",Transactions!$C$5:$C$504,$A25,Transactions!$I$5:$I$504,8,Transactions!$J$5:$J$504,Setup!$F$4)) | J25: =IF($A25="","",SUMIFS(Transactions!$E$5:$E$504,Transactions!$B$5:$B$504,"Expense",Transactions!$C$5:$C$504,$A25,Transactions!$I$5:$I$504,9,Transactions!$J$5:$J$504,Setup!$F$4)) | K25: =IF($A25="","",SUMIFS(Transactions!$E$5:$E$504,Transactions!$B$5:$B$504,"Expense",Transactions!$C$5:$C$504,$A25,Transactions!$I$5:$I$504,10,Transactions!$J$5:$J$504,Setup!$F$4)) | L25: =IF($A25="","",SUMIFS(Transactions!$E$5:$E$504,Transactions!$B$5:$B$504,"Expense",Transactions!$C$5:$C$504,$A25,Transactions!$I$5:$I$504,11,Transactions!$J$5:$J$504,Setup!$F$4)) | M25: =IF($A25="","",SUMIFS(Transactions!$E$5:$E$504,Transactions!$B$5:$B$504,"Expense",Transactions!$C$5:$C$504,$A25,Transactions!$I$5:$I$504,12,Transactions!$J$5:$J$504,Setup!$F$4)) | N25: =IF($A25="","",SUM(B25:M25)) | O25: =IF($A25="","",N25/12)
A26: =IF(Setup!D16="","",Setup!D16) | B26: =IF($A26="","",SUMIFS(Transactions!$E$5:$E$504,Transactions!$B$5:$B$504,"Expense",Transactions!$C$5:$C$504,$A26,Transactions!$I$5:$I$504,1,Transactions!$J$5:$J$504,Setup!$F$4)) | C26: =IF($A26="","",SUMIFS(Transactions!$E$5:$E$504,Transactions!$B$5:$B$504,"Expense",Transactions!$C$5:$C$504,$A26,Transactions!$I$5:$I$504,2,Transactions!$J$5:$J$504,Setup!$F$4)) | D26: =IF($A26="","",SUMIFS(Transactions!$E$5:$E$504,Transactions!$B$5:$B$504,"Expense",Transactions!$C$5:$C$504,$A26,Transactions!$I$5:$I$504,3,Transactions!$J$5:$J$504,Setup!$F$4)) | E26: =IF($A26="","",SUMIFS(Transactions!$E$5:$E$504,Transactions!$B$5:$B$504,"Expense",Transactions!$C$5:$C$504,$A26,Transactions!$I$5:$I$504,4,Transactions!$J$5:$J$504,Setup!$F$4)) | F26: =IF($A26="","",SUMIFS(Transactions!$E$5:$E$504,Transactions!$B$5:$B$504,"Expense",Transactions!$C$5:$C$504,$A26,Transactions!$I$5:$I$504,5,Transactions!$J$5:$J$504,Setup!$F$4)) | G26: =IF($A26="","",SUMIFS(Transactions!$E$5:$E$504,Transactions!$B$5:$B$504,"Expense",Transactions!$C$5:$C$504,$A26,Transactions!$I$5:$I$504,6,Transactions!$J$5:$J$504,Setup!$F$4)) | H26: =IF($A26="","",SUMIFS(Transactions!$E$5:$E$504,Transactions!$B$5:$B$504,"Expense",Transactions!$C$5:$C$504,$A26,Transactions!$I$5:$I$504,7,Transactions!$J$5:$J$504,Setup!$F$4)) | I26: =IF($A26="","",SUMIFS(Transactions!$E$5:$E$504,Transactions!$B$5:$B$504,"Expense",Transactions!$C$5:$C$504,$A26,Transactions!$I$5:$I$504,8,Transactions!$J$5:$J$504,Setup!$F$4)) | J26: =IF($A26="","",SUMIFS(Transactions!$E$5:$E$504,Transactions!$B$5:$B$504,"Expense",Transactions!$C$5:$C$504,$A26,Transactions!$I$5:$I$504,9,Transactions!$J$5:$J$504,Setup!$F$4)) | K26: =IF($A26="","",SUMIFS(Transactions!$E$5:$E$504,Transactions!$B$5:$B$504,"Expense",Transactions!$C$5:$C$504,$A26,Transactions!$I$5:$I$504,10,Transactions!$J$5:$J$504,Setup!$F$4)) | L26: =IF($A26="","",SUMIFS(Transactions!$E$5:$E$504,Transactions!$B$5:$B$504,"Expense",Transactions!$C$5:$C$504,$A26,Transactions!$I$5:$I$504,11,Transactions!$J$5:$J$504,Setup!$F$4)) | M26: =IF($A26="","",SUMIFS(Transactions!$E$5:$E$504,Transactions!$B$5:$B$504,"Expense",Transactions!$C$5:$C$504,$A26,Transactions!$I$5:$I$504,12,Transactions!$J$5:$J$504,Setup!$F$4)) | N26: =IF($A26="","",SUM(B26:M26)) | O26: =IF($A26="","",N26/12)
A27: =IF(Setup!D17="","",Setup!D17) | B27: =IF($A27="","",SUMIFS(Transactions!$E$5:$E$504,Transactions!$B$5:$B$504,"Expense",Transactions!$C$5:$C$504,$A27,Transactions!$I$5:$I$504,1,Transactions!$J$5:$J$504,Setup!$F$4)) | C27: =IF($A27="","",SUMIFS(Transactions!$E$5:$E$504,Transactions!$B$5:$B$504,"Expense",Transactions!$C$5:$C$504,$A27,Transactions!$I$5:$I$504,2,Transactions!$J$5:$J$504,Setup!$F$4)) | D27: =IF($A27="","",SUMIFS(Transactions!$E$5:$E$504,Transactions!$B$5:$B$504,"Expense",Transactions!$C$5:$C$504,$A27,Transactions!$I$5:$I$504,3,Transactions!$J$5:$J$504,Setup!$F$4)) | E27: =IF($A27="","",SUMIFS(Transactions!$E$5:$E$504,Transactions!$B$5:$B$504,"Expense",Transactions!$C$5:$C$504,$A27,Transactions!$I$5:$I$504,4,Transactions!$J$5:$J$504,Setup!$F$4)) | F27: =IF($A27="","",SUMIFS(Transactions!$E$5:$E$504,Transactions!$B$5:$B$504,"Expense",Transactions!$C$5:$C$504,$A27,Transactions!$I$5:$I$504,5,Transactions!$J$5:$J$504,Setup!$F$4)) | G27: =IF($A27="","",SUMIFS(Transactions!$E$5:$E$504,Transactions!$B$5:$B$504,"Expense",Transactions!$C$5:$C$504,$A27,Transactions!$I$5:$I$504,6,Transactions!$J$5:$J$504,Setup!$F$4)) | H27: =IF($A27="","",SUMIFS(Transactions!$E$5:$E$504,Transactions!$B$5:$B$504,"Expense",Transactions!$C$5:$C$504,$A27,Transactions!$I$5:$I$504,7,Transactions!$J$5:$J$504,Setup!$F$4)) | I27: =IF($A27="","",SUMIFS(Transactions!$E$5:$E$504,Transactions!$B$5:$B$504,"Expense",Transactions!$C$5:$C$504,$A27,Transactions!$I$5:$I$504,8,Transactions!$J$5:$J$504,Setup!$F$4)) | J27: =IF($A27="","",SUMIFS(Transactions!$E$5:$E$504,Transactions!$B$5:$B$504,"Expense",Transactions!$C$5:$C$504,$A27,Transactions!$I$5:$I$504,9,Transactions!$J$5:$J$504,Setup!$F$4)) | K27: =IF($A27="","",SUMIFS(Transactions!$E$5:$E$504,Transactions!$B$5:$B$504,"Expense",Transactions!$C$5:$C$504,$A27,Transactions!$I$5:$I$504,10,Transactions!$J$5:$J$504,Setup!$F$4)) | L27: =IF($A27="","",SUMIFS(Transactions!$E$5:$E$504,Transactions!$B$5:$B$504,"Expense",Transactions!$C$5:$C$504,$A27,Transactions!$I$5:$I$504,11,Transactions!$J$5:$J$504,Setup!$F$4)) | M27: =IF($A27="","",SUMIFS(Transactions!$E$5:$E$504,Transactions!$B$5:$B$504,"Expense",Transactions!$C$5:$C$504,$A27,Transactions!$I$5:$I$504,12,Transactions!$J$5:$J$504,Setup!$F$4)) | N27: =IF($A27="","",SUM(B27:M27)) | O27: =IF($A27="","",N27/12)
A28: =IF(Setup!D18="","",Setup!D18) | B28: =IF($A28="","",SUMIFS(Transactions!$E$5:$E$504,Transactions!$B$5:$B$504,"Expense",Transactions!$C$5:$C$504,$A28,Transactions!$I$5:$I$504,1,Transactions!$J$5:$J$504,Setup!$F$4)) | C28: =IF($A28="","",SUMIFS(Transactions!$E$5:$E$504,Transactions!$B$5:$B$504,"Expense",Transactions!$C$5:$C$504,$A28,Transactions!$I$5:$I$504,2,Transactions!$J$5:$J$504,Setup!$F$4)) | D28: =IF($A28="","",SUMIFS(Transactions!$E$5:$E$504,Transactions!$B$5:$B$504,"Expense",Transactions!$C$5:$C$504,$A28,Transactions!$I$5:$I$504,3,Transactions!$J$5:$J$504,Setup!$F$4)) | E28: =IF($A28="","",SUMIFS(Transactions!$E$5:$E$504,Transactions!$B$5:$B$504,"Expense",Transactions!$C$5:$C$504,$A28,Transactions!$I$5:$I$504,4,Transactions!$J$5:$J$504,Setup!$F$4)) | F28: =IF($A28="","",SUMIFS(Transactions!$E$5:$E$504,Transactions!$B$5:$B$504,"Expense",Transactions!$C$5:$C$504,$A28,Transactions!$I$5:$I$504,5,Transactions!$J$5:$J$504,Setup!$F$4)) | G28: =IF($A28="","",SUMIFS(Transactions!$E$5:$E$504,Transactions!$B$5:$B$504,"Expense",Transactions!$C$5:$C$504,$A28,Transactions!$I$5:$I$504,6,Transactions!$J$5:$J$504,Setup!$F$4)) | H28: =IF($A28="","",SUMIFS(Transactions!$E$5:$E$504,Transactions!$B$5:$B$504,"Expense",Transactions!$C$5:$C$504,$A28,Transactions!$I$5:$I$504,7,Transactions!$J$5:$J$504,Setup!$F$4)) | I28: =IF($A28="","",SUMIFS(Transactions!$E$5:$E$504,Transactions!$B$5:$B$504,"Expense",Transactions!$C$5:$C$504,$A28,Transactions!$I$5:$I$504,8,Transactions!$J$5:$J$504,Setup!$F$4)) | J28: =IF($A28="","",SUMIFS(Transactions!$E$5:$E$504,Transactions!$B$5:$B$504,"Expense",Transactions!$C$5:$C$504,$A28,Transactions!$I$5:$I$504,9,Transactions!$J$5:$J$504,Setup!$F$4)) | K28: =IF($A28="","",SUMIFS(Transactions!$E$5:$E$504,Transactions!$B$5:$B$504,"Expense",Transactions!$C$5:$C$504,$A28,Transactions!$I$5:$I$504,10,Transactions!$J$5:$J$504,Setup!$F$4)) | L28: =IF($A28="","",SUMIFS(Transactions!$E$5:$E$504,Transactions!$B$5:$B$504,"Expense",Transactions!$C$5:$C$504,$A28,Transactions!$I$5:$I$504,11,Transactions!$J$5:$J$504,Setup!$F$4)) | M28: =IF($A28="","",SUMIFS(Transactions!$E$5:$E$504,Transactions!$B$5:$B$504,"Expense",Transactions!$C$5:$C$504,$A28,Transactions!$I$5:$I$504,12,Transactions!$J$5:$J$504,Setup!$F$4)) | N28: =IF($A28="","",SUM(B28:M28)) | O28: =IF($A28="","",N28/12)
... A30: =IF(Setup!D20="","",Setup!D20) | B30: =IF($A30="","",SUMIFS(Transactions!$E$5:$E$504,Transactions!$B$5:$B$504,"Expense",Transactions!$C$5:$C$504,$A30,Transactions!$I$5:$I$504,1,Transactions!$J$5:$J$504,Setup!$F$4)) | C30: =IF($A30="","",SUMIFS(Transactions!$E$5:$E$504,Transactions!$B$5:$B$504,"Expense",Transactions!$C$5:$C$504,$A30,Transactions!$I$5:$I$504,2,Transactions!$J$5:$J$504,Setup!$F$4)) | D30: =IF($A30="","",SUMIFS(Transactions!$E$5:$E$504,Transactions!$B$5:$B$504,"Expense",Transactions!$C$5:$C$504,$A30,Transactions!$I$5:$I$504,3,Transactions!$J$5:$J$504,Setup!$F$4)) | E30: =IF($A30="","",SUMIFS(Transactions!$E$5:$E$504,Transactions!$B$5:$B$504,"Expense",Transactions!$C$5:$C$504,$A30,Transactions!$I$5:$I$504,4,Transactions!$J$5:$J$504,Setup!$F$4)) | F30: =IF($A30="","",SUMIFS(Transactions!$E$5:$E$504,Transactions!$B$5:$B$504,"Expense",Transactions!$C$5:$C$504,$A30,Transactions!$I$5:$I$504,5,Transactions!$J$5:$J$504,Setup!$F$4)) | G30: =IF($A30="","",SUMIFS(Transactions!$E$5:$E$504,Transactions!$B$5:$B$504,"Expense",Transactions!$C$5:$C$504,$A30,Transactions!$I$5:$I$504,6,Transactions!$J$5:$J$504,Setup!$F$4)) | H30: =IF($A30="","",SUMIFS(Transactions!$E$5:$E$504,Transactions!$B$5:$B$504,"Expense",Transactions!$C$5:$C$504,$A30,Transactions!$I$5:$I$504,7,Transactions!$J$5:$J$504,Setup!$F$4)) | I30: =IF($A30="","",SUMIFS(Transactions!$E$5:$E$504,Transactions!$B$5:$B$504,"Expense",Transactions!$C$5:$C$504,$A30,Transactions!$I$5:$I$504,8,Transactions!$J$5:$J$504,Setup!$F$4)) | J30: =IF($A30="","",SUMIFS(Transactions!$E$5:$E$504,Transactions!$B$5:$B$504,"Expense",Transactions!$C$5:$C$504,$A30,Transactions!$I$5:$I$504,9,Transactions!$J$5:$J$504,Setup!$F$4)) | K30: =IF($A30="","",SUMIFS(Transactions!$E$5:$E$504,Transactions!$B$5:$B$504,"Expense",Transactions!$C$5:$C$504,$A30,Transactions!$I$5:$I$504,10,Transactions!$J$5:$J$504,Setup!$F$4)) | L30: =IF($A30="","",SUMIFS(Transactions!$E$5:$E$504,Transactions!$B$5:$B$504,"Expense",Transactions!$C$5:$C$504,$A30,Transactions!$I$5:$I$504,11,Transactions!$J$5:$J$504,Setup!$F$4)) | M30: =IF($A30="","",SUMIFS(Transactions!$E$5:$E$504,Transactions!$B$5:$B$504,"Expense",Transactions!$C$5:$C$504,$A30,Transactions!$I$5:$I$504,12,Transactions!$J$5:$J$504,Setup!$F$4)) | N30: =IF($A30="","",SUM(B30:M30)) | O30: =IF($A30="","",N30/12)
A32: 50 / 30 / 20 (year)
B33: Actual | C33: Target | D33: Diff
A34: Needs | B34: =SUMIFS(Transactions!$E$5:$E$504,Transactions!$B$5:$B$504,"Expense",Transactions!$K$5:$K$504,"needs",Transactions!$J$5:$J$504,Setup!$F$4)+IF("needs"="savings",SUMIFS(Transactions!$E$5:$E$504,Transactions!$B$5:$B$504,"Transfer",Transactions!$J$5:$J$504,Setup!$F$4),0) | C34: =IF(Setup!$J$4=0,$B$7*0.5,Setup!$J$4*12*0.5) | D34: =C34-B34
A35: Wants | B35: =SUMIFS(Transactions!$E$5:$E$504,Transactions!$B$5:$B$504,"Expense",Transactions!$K$5:$K$504,"wants",Transactions!$J$5:$J$504,Setup!$F$4)+IF("wants"="savings",SUMIFS(Transactions!$E$5:$E$504,Transactions!$B$5:$B$504,"Transfer",Transactions!$J$5:$J$504,Setup!$F$4),0) | C35: =IF(Setup!$J$4=0,$B$7*0.3,Setup!$J$4*12*0.3) | D35: =C35-B35
A36: Savings | B36: =SUMIFS(Transactions!$E$5:$E$504,Transactions!$B$5:$B$504,"Expense",Transactions!$K$5:$K$504,"savings",Transactions!$J$5:$J$504,Setup!$F$4)+IF("savings"="savings",SUMIFS(Transactions!$E$5:$E$504,Transactions!$B$5:$B$504,"Transfer",Transactions!$J$5:$J$504,Setup!$F$4),0) | C36: =IF(Setup!$J$4=0,$B$7*0.2,Setup!$J$4*12*0.2) | D36: =C36-B36

Sheet 50-30-20 Rule
A1: 50 / 30 / 20 Rule
A2: How your spending splits into Needs, Wants and Savings — straight from your logged transactions.
B5: TARGET | C5: ACTUAL | D5: % OF INCOME | E5: STATUS
A6: Needs | B6: 0.5 | C6: =SUMIFS(Transactions!$E$5:$E$504,Transactions!$K$5:$K$504,"needs",Transactions!$J$5:$J$504,Setup!$F$4,Transactions!$B$5:$B$504,"Expense") | D6: =IFERROR(C6/$B$10,0) | E6: =IF($B$10=0,"—",IF(D6<=B6,"On track","Over"))
A7: Wants | B7: 0.3 | C7: =SUMIFS(Transactions!$E$5:$E$504,Transactions!$K$5:$K$504,"wants",Transactions!$J$5:$J$504,Setup!$F$4,Transactions!$B$5:$B$504,"Expense") | D7: =IFERROR(C7/$B$10,0) | E7: =IF($B$10=0,"—",IF(D7<=B7,"On track","Over"))
A8: Savings | B8: 0.2 | C8: =SUMIFS(Transactions!$E$5:$E$504,Transactions!$K$5:$K$504,"savings",Transactions!$J$5:$J$504,Setup!$F$4,Transactions!$B$5:$B$504,"Expense")+SUMIFS(Transactions!$E$5:$E$504,Transactions!$B$5:$B$504,"Transfer",Transactions!$J$5:$J$504,Setup!$F$4) | D8: =IFERROR(C8/$B$10,0) | E8: =IF($B$10=0,"—",IF(D8>=B8,"On track","Below"))
A10: Annual income | B10: =SUMIFS(Transactions!$E$5:$E$504,Transactions!$B$5:$B$504,"Income",Transactions!$J$5:$J$504,Setup!$F$4)
A11: Left to allocate | B11: =B10-C6-C7-C8
A13: Tip: tag each category as needs / wants / savings on the Setup tab.

Sheet Spending Tracker
A1: Spending Tracker
A2: Where your money goes — by category, this year.
A5: CATEGORY | B5: SPENT | C5: % OF SPENDING
A6: =Setup!$D$7 | B6: =SUMIFS(Transactions!$E$5:$E$504,Transactions!$C$5:$C$504,Setup!$D$7,Transactions!$B$5:$B$504,"Expense",Transactions!$J$5:$J$504,Setup!$F$4) | C6: =IFERROR(B6/$B$21,0)
A7: =Setup!$D$8 | B7: =SUMIFS(Transactions!$E$5:$E$504,Transactions!$C$5:$C$504,Setup!$D$8,Transactions!$B$5:$B$504,"Expense",Transactions!$J$5:$J$504,Setup!$F$4) | C7: =IFERROR(B7/$B$21,0)
A8: =Setup!$D$9 | B8: =SUMIFS(Transactions!$E$5:$E$504,Transactions!$C$5:$C$504,Setup!$D$9,Transactions!$B$5:$B$504,"Expense",Transactions!$J$5:$J$504,Setup!$F$4) | C8: =IFERROR(B8/$B$21,0)
A9: =Setup!$D$10 | B9: =SUMIFS(Transactions!$E$5:$E$504,Transactions!$C$5:$C$504,Setup!$D$10,Transactions!$B$5:$B$504,"Expense",Transactions!$J$5:$J$504,Setup!$F$4) | C9: =IFERROR(B9/$B$21,0)
A10: =Setup!$D$11 | B10: =SUMIFS(Transactions!$E$5:$E$504,Transactions!$C$5:$C$504,Setup!$D$11,Transactions!$B$5:$B$504,"Expense",Transactions!$J$5:$J$504,Setup!$F$4) | C10: =IFERROR(B10/$B$21,0)
A11: =Setup!$D$12 | B11: =SUMIFS(Transactions!$E$5:$E$504,Transactions!$C$5:$C$504,Setup!$D$12,Transactions!$B$5:$B$504,"Expense",Transactions!$J$5:$J$504,Setup!$F$4) | C11: =IFERROR(B11/$B$21,0)
A12: =Setup!$D$13 | B12: =SUMIFS(Transactions!$E$5:$E$504,Transactions!$C$5:$C$504,Setup!$D$13,Transactions!$B$5:$B$504,"Expense",Transactions!$J$5:$J$504,Setup!$F$4) | C12: =IFERROR(B12/$B$21,0)
A13: =Setup!$D$14 | B13: =SUMIFS(Transactions!$E$5:$E$504,Transactions!$C$5:$C$504,Setup!$D$14,Transactions!$B$5:$B$504,"Expense",Transactions!$J$5:$J$504,Setup!$F$4) | C13: =IFERROR(B13/$B$21,0)
A14: =Setup!$D$15 | B14: =SUMIFS(Transactions!$E$5:$E$504,Transactions!$C$5:$C$504,Setup!$D$15,Transactions!$B$5:$B$504,"Expense",Transactions!$J$5:$J$504,Setup!$F$4) | C14: =IFERROR(B14/$B$21,0)
A15: =Setup!$D$16 | B15: =SUMIFS(Transactions!$E$5:$E$504,Transactions!$C$5:$C$504,Setup!$D$16,Transactions!$B$5:$B$504,"Expense",Transactions!$J$5:$J$504,Setup!$F$4) | C15: =IFERROR(B15/$B$21,0)
A16: =Setup!$D$17 | B16: =SUMIFS(Transactions!$E$5:$E$504,Transactions!$C$5:$C$504,Setup!$D$17,Transactions!$B$5:$B$504,"Expense",Transactions!$J$5:$J$504,Setup!$F$4) | C16: =IFERROR(B16/$B$21,0)
A17: =Setup!$D$18 | B17: =SUMIFS(Transactions!$E$5:$E$504,Transactions!$C$5:$C$504,Setup!$D$18,Transactions!$B$5:$B$504,"Expense",Transactions!$J$5:$J$504,Setup!$F$4) | C17: =IFERROR(B17/$B$21,0)
A18: =Setup!$D$19 | B18: =SUMIFS(Transactions!$E$5:$E$504,Transactions!$C$5:$C$504,Setup!$D$19,Transactions!$B$5:$B$504,"Expense",Transactions!$J$5:$J$504,Setup!$F$4) | C18: =IFERROR(B18/$B$21,0)
A19: =Setup!$D$20 | B19: =SUMIFS(Transactions!$E$5:$E$504,Transactions!$C$5:$C$504,Setup!$D$20,Transactions!$B$5:$B$504,"Expense",Transactions!$J$5:$J$504,Setup!$F$4) | C19: =IFERROR(B19/$B$21,0)
A21: Total spending | B21: =SUMIFS(Transactions!$E$5:$E$504,Transactions!$B$5:$B$504,"Expense",Transactions!$J$5:$J$504,Setup!$F$4)
A23: Top category | B23: =IF($B$21=0,"—",IFERROR(INDEX(A6:A19,MATCH(MAX(B6:B19),B6:B19,0)),"—"))

Sheet Split and Settle
B1: Split and Settle Up
B2: Mark who paid on Transactions. This works out a fair split and who owes whom.
B4: Split mode | C4: =Setup!$N$13
B5: Partner A share | C5: =Setup!$N$16
B6: Partner B share | C6: =Setup!$N$17
B8: SHARED EXPENSES | C8: =Setup!$N$7 | D8: =Setup!$N$8 | E8: Joint
B9: Paid (shared) | C9: =SUMIFS(Transactions!$E$5:$E$504,Transactions!$B$5:$B$504,"Expense",Transactions!$G$5:$G$504,"Shared",Transactions!$F$5:$F$504,Setup!$N$7) | D9: =SUMIFS(Transactions!$E$5:$E$504,Transactions!$B$5:$B$504,"Expense",Transactions!$G$5:$G$504,"Shared",Transactions!$F$5:$F$504,Setup!$N$8) | E9: =SUMIFS(Transactions!$E$5:$E$504,Transactions!$B$5:$B$504,"Expense",Transactions!$G$5:$G$504,"Shared",Transactions!$F$5:$F$504,"Joint")
B11: Shared to split (A+B) | C11: =C9+D9
B12: Fair share | C12: =$C$11*Setup!$N$16 | D12: =$C$11*Setup!$N$17
B13: Difference (paid − fair) | C13: =C9-C12 | D13: =D9-D12
B14: Contribution % | C14: =IF($C$11=0,0,C9/$C$11) | D14: =IF($C$11=0,0,D9/$C$11)
B16: =IF(C13>0,Setup!$N$8&" owes "&Setup!$N$7&" "&TEXT(C13,"$#,##0.00"),IF(C13<0,Setup!$N$7&" owes "&Setup!$N$8&" "&TEXT(-C13,"$#,##0.00"),"All settled up"))
B18: Check | C18: =IF(SUMPRODUCT((Transactions!$G$5:$G$504="Shared")*(Transactions!$F$5:$F$504="")*(Transactions!$B$5:$B$504="Expense"))>0,SUMPRODUCT((Transactions!$G$5:$G$504="Shared")*(Transactions!$F$5:$F$504="")*(Transactions!$B$5:$B$504="Expense"))&" shared expense(s) missing Paid by — fix on Transactions","No errors ✓")
B20: Personal (each pays own)
B21: Personal spend | C21: =SUMIFS(Transactions!$E$5:$E$504,Transactions!$B$5:$B$504,"Expense",Transactions!$G$5:$G$504,"Personal",Transactions!$F$5:$F$504,Setup!$N$7) | D21: =SUMIFS(Transactions!$E$5:$E$504,Transactions!$B$5:$B$504,"Expense",Transactions!$G$5:$G$504,"Personal",Transactions!$F$5:$F$504,Setup!$N$8)

Sheet Month View
A1: Month View
A2: Pick a month to see it on its own. No re-typing — it reads your Transactions.
B4: Pick month (1-12) | D4: 1
B6: INCOME | D6: EXPENSES | F6: SAVED | H6: LEFT
B7: =SUMIFS(Transactions!$E$5:$E$504,Transactions!$B$5:$B$504,"Income",Transactions!$I$5:$I$504,$D$4,Transactions!$J$5:$J$504,Setup!$F$4) | D7: =SUMIFS(Transactions!$E$5:$E$504,Transactions!$B$5:$B$504,"Expense",Transactions!$I$5:$I$504,$D$4,Transactions!$J$5:$J$504,Setup!$F$4) | F7: =SUMIFS(Transactions!$E$5:$E$504,Transactions!$B$5:$B$504,"Transfer",Transactions!$I$5:$I$504,$D$4,Transactions!$J$5:$J$504,Setup!$F$4) | H7: =B7-D7-F7
B10: SPENDING THIS MONTH BY CATEGORY
B11: Category | C11: Spent | D11: % of expenses
B12: =IF(Setup!D7="","",Setup!D7) | C12: =IF($B12="","",SUMIFS(Transactions!$E$5:$E$504,Transactions!$B$5:$B$504,"Expense",Transactions!$C$5:$C$504,$B12,Transactions!$I$5:$I$504,$D$4,Transactions!$J$5:$J$504,Setup!$F$4)) | D12: =IF(OR($B12="",$D$7=0),"",C12/$D$7)
B13: =IF(Setup!D8="","",Setup!D8) | C13: =IF($B13="","",SUMIFS(Transactions!$E$5:$E$504,Transactions!$B$5:$B$504,"Expense",Transactions!$C$5:$C$504,$B13,Transactions!$I$5:$I$504,$D$4,Transactions!$J$5:$J$504,Setup!$F$4)) | D13: =IF(OR($B13="",$D$7=0),"",C13/$D$7)
B14: =IF(Setup!D9="","",Setup!D9) | C14: =IF($B14="","",SUMIFS(Transactions!$E$5:$E$504,Transactions!$B$5:$B$504,"Expense",Transactions!$C$5:$C$504,$B14,Transactions!$I$5:$I$504,$D$4,Transactions!$J$5:$J$504,Setup!$F$4)) | D14: =IF(OR($B14="",$D$7=0),"",C14/$D$7)
B15: =IF(Setup!D10="","",Setup!D10) | C15: =IF($B15="","",SUMIFS(Transactions!$E$5:$E$504,Transactions!$B$5:$B$504,"Expense",Transactions!$C$5:$C$504,$B15,Transactions!$I$5:$I$504,$D$4,Transactions!$J$5:$J$504,Setup!$F$4)) | D15: =IF(OR($B15="",$D$7=0),"",C15/$D$7)
B16: =IF(Setup!D11="","",Setup!D11) | C16: =IF($B16="","",SUMIFS(Transactions!$E$5:$E$504,Transactions!$B$5:$B$504,"Expense",Transactions!$C$5:$C$504,$B16,Transactions!$I$5:$I$504,$D$4,Transactions!$J$5:$J$504,Setup!$F$4)) | D16: =IF(OR($B16="",$D$7=0),"",C16/$D$7)
B17: =IF(Setup!D12="","",Setup!D12) | C17: =IF($B17="","",SUMIFS(Transactions!$E$5:$E$504,Transactions!$B$5:$B$504,"Expense",Transactions!$C$5:$C$504,$B17,Transactions!$I$5:$I$504,$D$4,Transactions!$J$5:$J$504,Setup!$F$4)) | D17: =IF(OR($B17="",$D$7=0),"",C17/$D$7)
B18: =IF(Setup!D13="","",Setup!D13) | C18: =IF($B18="","",SUMIFS(Transactions!$E$5:$E$504,Transactions!$B$5:$B$504,"Expense",Transactions!$C$5:$C$504,$B18,Transactions!$I$5:$I$504,$D$4,Transactions!$J$5:$J$504,Setup!$F$4)) | D18: =IF(OR($B18="",$D$7=0),"",C18/$D$7)
B19: =IF(Setup!D14="","",Setup!D14) | C19: =IF($B19="","",SUMIFS(Transactions!$E$5:$E$504,Transactions!$B$5:$B$504,"Expense",Transactions!$C$5:$C$504,$B19,Transactions!$I$5:$I$504,$D$4,Transactions!$J$5:$J$504,Setup!$F$4)) | D19: =IF(OR($B19="",$D$7=0),"",C19/$D$7)
B20: =IF(Setup!D15="","",Setup!D15) | C20: =IF($B20="","",SUMIFS(Transactions!$E$5:$E$504,Transactions!$B$5:$B$504,"Expense",Transactions!$C$5:$C$504,$B20,Transactions!$I$5:$I$504,$D$4,Transactions!$J$5:$J$504,Setup!$F$4)) | D20: =IF(OR($B20="",$D$7=0),"",C20/$D$7)
B21: =IF(Setup!D16="","",Setup!D16) | C21: =IF($B21="","",SUMIFS(Transactions!$E$5:$E$504,Transactions!$B$5:$B$504,"Expense",Transactions!$C$5:$C$504,$B21,Transactions!$I$5:$I$504,$D$4,Transactions!$J$5:$J$504,Setup!$F$4)) | D21: =IF(OR($B21="",$D$7=0),"",C21/$D$7)
B22: =IF(Setup!D17="","",Setup!D17) | C22: =IF($B22="","",SUMIFS(Transactions!$E$5:$E$504,Transactions!$B$5:$B$504,"Expense",Transactions!$C$5:$C$504,$B22,Transactions!$I$5:$I$504,$D$4,Transactions!$J$5:$J$504,Setup!$F$4)) | D22: =IF(OR($B22="",$D$7=0),"",C22/$D$7)
B23: =IF(Setup!D18="","",Setup!D18) | C23: =IF($B23="","",SUMIFS(Transactions!$E$5:$E$504,Transactions!$B$5:$B$504,"Expense",Transactions!$C$5:$C$504,$B23,Transactions!$I$5:$I$504,$D$4,Transactions!$J$5:$J$504,Setup!$F$4)) | D23: =IF(OR($B23="",$D$7=0),"",C23/$D$7)
... B25: =IF(Setup!D20="","",Setup!D20) | C25: =IF($B25="","",SUMIFS(Transactions!$E$5:$E$504,Transactions!$B$5:$B$504,"Expense",Transactions!$C$5:$C$504,$B25,Transactions!$I$5:$I$504,$D$4,Transactions!$J$5:$J$504,Setup!$F$4)) | D25: =IF(OR($B25="",$D$7=0),"",C25/$D$7)

Sheet Bill Calendar
A1: Bill Calendar
A2: Set the frequency, see the true monthly and yearly cost, never miss a due day.
A4: Bill | B4: Amount | C4: Frequency | D4: Monthly cost | E4: Yearly cost | F4: Due day | G4: Paid?
A5: Rent or Mortgage | B5: 2400 | C5: Monthly | D5: =IF(OR(B5="",C5=""),"",B5*IF(C5="Weekly",4.3333,IF(C5="Biweekly",2.1667,IF(C5="Monthly",1,IF(C5="Quarterly",1/3,IF(C5="Yearly",1/12,0)))))) | E5: =IF(D5="","",D5*12) | F5: 1 | G5: Yes
A6: Electricity | B6: 130 | C6: Monthly | D6: =IF(OR(B6="",C6=""),"",B6*IF(C6="Weekly",4.3333,IF(C6="Biweekly",2.1667,IF(C6="Monthly",1,IF(C6="Quarterly",1/3,IF(C6="Yearly",1/12,0)))))) | E6: =IF(D6="","",D6*12) | F6: 8 | G6: Yes
A7: Water | B7: 210 | C7: Quarterly | D7: =IF(OR(B7="",C7=""),"",B7*IF(C7="Weekly",4.3333,IF(C7="Biweekly",2.1667,IF(C7="Monthly",1,IF(C7="Quarterly",1/3,IF(C7="Yearly",1/12,0)))))) | E7: =IF(D7="","",D7*12) | F7: 12 | G7: No
A8: Internet | B8: 60 | C8: Monthly | D8: =IF(OR(B8="",C8=""),"",B8*IF(C8="Weekly",4.3333,IF(C8="Biweekly",2.1667,IF(C8="Monthly",1,IF(C8="Quarterly",1/3,IF(C8="Yearly",1/12,0)))))) | E8: =IF(D8="","",D8*12) | F8: 15 | G8: Yes
A9: Mobile phones | B9: 50 | C9: Monthly | D9: =IF(OR(B9="",C9=""),"",B9*IF(C9="Weekly",4.3333,IF(C9="Biweekly",2.1667,IF(C9="Monthly",1,IF(C9="Quarterly",1/3,IF(C9="Yearly",1/12,0)))))) | E9: =IF(D9="","",D9*12) | F9: 15 | G9: Yes
A10: Council tax | B10: 195 | C10: Monthly | D10: =IF(OR(B10="",C10=""),"",B10*IF(C10="Weekly",4.3333,IF(C10="Biweekly",2.1667,IF(C10="Monthly",1,IF(C10="Quarterly",1/3,IF(C10="Yearly",1/12,0)))))) | E10: =IF(D10="","",D10*12) | F10: 20 | G10: Yes
A11: Home insurance | B11: 240 | C11: Yearly | D11: =IF(OR(B11="",C11=""),"",B11*IF(C11="Weekly",4.3333,IF(C11="Biweekly",2.1667,IF(C11="Monthly",1,IF(C11="Quarterly",1/3,IF(C11="Yearly",1/12,0)))))) | E11: =IF(D11="","",D11*12) | F11: 3 | G11: No
A12: Car insurance | B12: 620 | C12: Yearly | D12: =IF(OR(B12="",C12=""),"",B12*IF(C12="Weekly",4.3333,IF(C12="Biweekly",2.1667,IF(C12="Monthly",1,IF(C12="Quarterly",1/3,IF(C12="Yearly",1/12,0)))))) | E12: =IF(D12="","",D12*12) | F12: 9 | G12: No
A13: Netflix | B13: 15.99 | C13: Monthly | D13: =IF(OR(B13="",C13=""),"",B13*IF(C13="Weekly",4.3333,IF(C13="Biweekly",2.1667,IF(C13="Monthly",1,IF(C13="Quarterly",1/3,IF(C13="Yearly",1/12,0)))))) | E13: =IF(D13="","",D13*12) | F13: 18 | G13: Yes
A14: Spotify | B14: 11.99 | C14: Monthly | D14: =IF(OR(B14="",C14=""),"",B14*IF(C14="Weekly",4.3333,IF(C14="Biweekly",2.1667,IF(C14="Monthly",1,IF(C14="Quarterly",1/3,IF(C14="Yearly",1/12,0)))))) | E14: =IF(D14="","",D14*12) | F14: 22 | G14: Yes
